terminate called after throwing an instance of 'std::invalid_argument'
  what():  stoul
terminate called after throwing an instance of 'std::invalid_argument'
  what():  stoul
